Workbook

Sheet план
A10: https://www.semestr.online/web/pyramid.php
A11: где можно построить многоугольник по точкам

Sheet +V гексы
A1: как посчитать объем искаженной гегсы, которая имеет координаты
A3: точки | B3: X | C3: Y | D3: Z
A4: 1 | B4: 0 | C4: 0 | D4: 0
A5: 2 | B5: 12 | C5: 0 | D5: 0
A6: 3 | B6: 10 | C6: 10 | D6: 0
A7: 4 | B7: 0 | C7: 10 | D7: 0
A8: 5 | B8: 0 | C8: 0 | D8: 12
A9: 6 | B9: 10 | C9: 0 | D9: 10
A10: 7 | B10: 10 | C10: 10 | D10: 7
A11: 8 | B11: 0 | C11: 10 | D11: 10
A14: разбиение на тэтрадры
A16: 2 способа
B57: стр 107
A59: 6 тэтраэдров | N59: 5 тэтраэдров
A60: точки, образующие тэтраэдр | H60: V тэтр
A61: 5 | B61: =B8 -> 0 | C61: =C8 -> 0 | D61: =D8 -> 12 | E61: 1 | G61: =MDETERM(B61:E64) -> -960 | H61: =ABS(G61/6) -> 160 | N61: 5 | O61: =B8 -> 0 | P61: =C8 -> 0 | Q61: =D8 -> 12 | R61: 1 | T61: =MDETERM(O61:R64) -> 960 | U61: =ABS(T61/6) -> 160
A62: 7 | B62: =B10 -> 10 | C62: =C10 -> 10 | D62: =D10 -> 7 | E62: 1 | N62: 6 | O62: =B9 -> 10 | P62: =C9 -> 0 | Q62: =D9 -> 10 | R62: 1
A63: 6 | B63: =B9 -> 10 | C63: =C9 -> 0 | D63: =D9 -> 10 | E63: 1 | N63: 7 | O63: =B10 -> 10 | P63: =C10 -> 10 | Q63: =D10 -> 7 | R63: 1
A64: 2 | B64: =B5 -> 12 | C64: =C5 -> 0 | D64: =D5 -> 0 | E64: 1 | N64: 2 | O64: =B5 -> 12 | P64: =C5 -> 0 | Q64: =D5 -> 0 | R64: 1
A67: 5 | B67: =B8 -> 0 | C67: =C8 -> 0 | D67: =D8 -> 12 | E67: 1 | G67: =MDETERM(B67:E70) -> 1440 | H67: =ABS(G67/6) -> 240 | N67: 5 | O67: =B8 -> 0 | P67: =C8 -> 0 | Q67: =D8 -> 12 | R67: 1 | T67: =MDETERM(O67:R70) -> 1440 | U67: =ABS(T67/6) -> 240
A68: 2 | B68: =B5 -> 12 | C68: =C5 -> 0 | D68: =D5 -> 0 | E68: 1 | N68: 2 | O68: =B5 -> 12 | P68: =C5 -> 0 | Q68: =D5 -> 0 | R68: 1
A69: 3 | B69: =B6 -> 10 | C69: =C6 -> 10 | D69: =D6 -> 0 | E69: 1 | N69: 4 | O69: =B7 -> 0 | P69: =C7 -> 10 | Q69: =D7 -> 0 | R69: 1
A70: 1 | B70: =B4 -> 0 | C70: =C4 -> 0 | D70: =D4 -> 0 | E70: 1 | N70: 1 | O70: =B4 -> 0 | P70: =C4 -> 0 | Q70: =D4 -> 0 | R70: 1
A73: 7 | B73: =B10 -> 10 | C73: =C10 -> 10 | D73: =D10 -> 7 | E73: 1 | G73: =MDETERM(B73:E76) -> 840 | H73: =ABS(G73/6) -> 140 | N73: 7 | O73: =B10 -> 10 | P73: =C10 -> 10 | Q73: =D10 -> 7 | R73: 1 | T73: =MDETERM(O73:R76) -> 700 | U73: =ABS(T73/6) -> 116.66667
A74: 2 | B74: =B5 -> 12 | C74: =C5 -> 0 | D74: =D5 -> 0 | E74: 1 | N74: 2 | O74: =B5 -> 12 | P74: =C5 -> 0 | Q74: =D5 -> 0 | R74: 1
A75: 3 | B75: =B6 -> 10 | C75: =C6 -> 10 | D75: =D6 -> 0 | E75: 1 | N75: 3 | O75: =B6 -> 10 | P75: =C6 -> 10 | Q75: =D6 -> 0 | R75: 1
A76: 5 | B76: =B8 -> 0 | C76: =C8 -> 0 | D76: =D8 -> 12 | E76: 1 | N76: 4 | O76: =B7 -> 0 | P76: =C7 -> 10 | Q76: =D7 -> 0 | R76: 1
A79: 5 | B79: =B8 -> 0 | C79: =C8 -> 0 | D79: =D8 -> 12 | E79: 1 | G79: =MDETERM(B79:E82) -> 1000 | H79: =ABS(G79/6) -> 166.66667 | N79: 5 | O79: =B8 -> 0 | P79: =C8 -> 0 | Q79: =D8 -> 12 | R79: 1 | T79: =MDETERM(O79:R82) -> -1000 | U79: =ABS(T79/6) -> 166.66667
A80: 7 | B80: =B10 -> 10 | C80: =C10 -> 10 | D80: =D10 -> 7 | E80: 1 | N80: 8 | O80: =B11 -> 0 | P80: =C11 -> 10 | Q80: =D11 -> 10 | R80: 1
A81: 8 | B81: =B11 -> 0 | C81: =C11 -> 10 | D81: =D11 -> 10 | E81: 1 | N81: 7 | O81: =B10 -> 10 | P81: =C10 -> 10 | Q81: =D10 -> 7 | R81: 1
A82: 4 | B82: =B7 -> 0 | C82: =C7 -> 10 | D82: =D7 -> 0 | E82: 1 | N82: 4 | O82: =B7 -> 0 | P82: =C7 -> 10 | Q82: =D7 -> 0 | R82: 1
A85: 5 | B85: =B8 -> 0 | C85: =C8 -> 0 | D85: =D8 -> 12 | E85: 1 | G85: =MDETERM(B85:E88) -> 1200 | H85: =ABS(G85/6) -> 200 | N85: 5 | O85: =B8 -> 0 | P85: =C8 -> 0 | Q85: =D8 -> 12 | R85: 1 | T85: =MDETERM(O85:R88) -> 2040 | U85: =ABS(T85/6) -> 340
A86: 3 | B86: =B6 -> 10 | C86: =C6 -> 10 | D86: =D6 -> 0 | E86: 1 | N86: 7 | O86: =B10 -> 10 | P86: =C10 -> 10 | Q86: =D10 -> 7 | R86: 1
A87: 4 | B87: =B7 -> 0 | C87: =C7 -> 10 | D87: =D7 -> 0 | E87: 1 | N87: 4 | O87: =B7 -> 0 | P87: =C7 -> 10 | Q87: =D7 -> 0 | R87: 1
A88: 1 | B88: =B4 -> 0 | C88: =C4 -> 0 | D88: =D4 -> 0 | E88: 1 | N88: 2 | O88: =B5 -> 12 | P88: =C5 -> 0 | Q88: =D5 -> 0 | R88: 1
T90: V | U90: =SUM(U61:U89) -> 1023.3333
A91: 7 | B91: =B10 -> 10 | C91: =C10 -> 10 | D91: =D10 -> 7 | E91: 1 | G91: =MDETERM(B91:E94) -> 700 | H91: =ABS(G91/6) -> 116.66667
A92: 3 | B92: =B6 -> 10 | C92: =C6 -> 10 | D92: =D6 -> 0 | E92: 1
A93: 4 | B93: =B7 -> 0 | C93: =C7 -> 10 | D93: =D7 -> 0 | E93: 1
A94: 5 | B94: =B8 -> 0 | C94: =C8 -> 0 | D94: =D8 -> 12 | E94: 1
...

Sheet +!V гексы через якобиан
B2: x | C2: y | D2: z | F2: коэф | H2: точки интегрирования
A3: 1 | B3: 0 | C3: 0 | D3: 0 | F3: =1/8 -> 0.125 | H3: 0.57735
A4: 2 | B4: 12 | C4: 0 | D4: 0 | H4: =-H3 -> -0.57735
A5: 3 | B5: 10 | C5: 10 | D5: 0
A6: 4 | B6: 0 | C6: 10 | D6: 0
A7: 5 | B7: 0 | C7: 0 | D7: 12
A8: 6 | B8: 10 | C8: 0 | D8: 10
A9: 7 | B9: 10 | C9: 10 | D9: 7
A10: 8 | B10: 0 | C10: 10 | D10: 10
A13: слагаемые | B13: ось | C13: координата т. интегр. | E13: производные функции формы | N13: матрица Якоби (без коэффициента 1/8) | R13: матрица Якоби | V13: det[J]
A14: 1 | B14: ξ | C14: 0.57735 | E14: =-(1-C15)*(1-C16) -> -0.17863302 | F14: =(1-C15)*(1-C16) -> 0.17863302 | G14: =(1+C15)*(1-C16) -> 0.66666698 | H14: =-(1+C15)*(1-C16) -> -0.66666698 | I14: =-(1-C15)*(1+C16) -> -0.66666698 | J14: =(1-C15)*(1+C16) -> 0.66666698 | K14: =(1+C15)*(1+C16) -> 2.488033 | L14: =-(1+C15)*(1+C16) -> -2.488033 | N14: {=MMULT(E14:L16,$B$3:$D$10)} -> 40.357266 | O14: 0 | P14: -8.797433 | R14: =$F$3*N14 -> 5.0446583 | S14: =$F$3*O14 -> 0 | T14: =$F$3*P14 -> -1.0996791 | V14: =MDETERM(R14:T16) -> 102.79284
B15: η | C15: 0.57735 | E15: =-(1-C14)*(1-C16) -> -0.17863302 | F15: =-(1+C14)*(1-C16) -> -0.66666698 | G15: =(1+C14)*(1-C16) -> 0.66666698 | H15: =(1-C14)*(1-C16) -> 0.17863302 | I15: =-(1-C14)*(1+C16) -> -0.66666698 | J15: =-(1+C14)*(1+C16) -> -2.488033 | K15: =(1+C14)*(1+C16) -> 2.488033 | L15: =(1-C14)*(1+C16) -> 0.66666698 | N15: -1.333334 | O15: 40 | P15: -8.797433 | R15: =$F$3*N15 -> -0.16666674 | S15: =$F$3*O15 -> 5 | T15: =$F$3*P15 -> -1.0996791
B16: ζ | C16: 0.57735 | E16: =-(1-C14)*(1-C15) -> -0.17863302 | F16: =-(1+C14)*(1-C15) -> -0.66666698 | G16: =-(1+C14)*(1+C15) -> -2.488033 | H16: =-(1-C14)*(1+C15) -> -0.66666698 | I16: =(1-C14)*(1-C15) -> 0.17863302 | J16: =(1+C14)*(1-C15) -> 0.66666698 | K16: =(1+C14)*(1+C15) -> 2.488033 | L16: =(1-C14)*(1+C15) -> 0.66666698 | N16: -1.333334 | O16: 0 | P16: 32.893167 | R16: =$F$3*N16 -> -0.16666674 | S16: =$F$3*O16 -> 0 | T16: =$F$3*P16 -> 4.1116459
A18: 2 | B18: ξ | C18: 0.57735 | E18: =-(1-C19)*(1-C20) -> -0.66666698 | F18: =(1-C19)*(1-C20) -> 0.66666698 | G18: =(1+C19)*(1-C20) -> 2.488033 | H18: =-(1+C19)*(1-C20) -> -2.488033 | I18: =-(1-C19)*(1+C20) -> -0.17863302 | J18: =(1-C19)*(1+C20) -> 0.17863302 | K18: =(1+C19)*(1+C20) -> 0.66666698 | L18: =-(1+C19)*(1+C20) -> -0.66666698 | N18: {=MMULT(E18:L20,$B$3:$D$10)} -> 41.333334 | O18: 0 | P18: -2.357267 | R18: =$F$3*N18 -> 5.1666667 | S18: =$F$3*O18 -> 0 | T18: =$F$3*P18 -> -0.29465837 | V18: =MDETERM(R18:T20) -> 105.97197
B19: η | C19: 0.57735 | E19: =-(1-C18)*(1-C20) -> -0.66666698 | F19: =-(1+C18)*(1-C20) -> -2.488033 | G19: =(1+C18)*(1-C20) -> 2.488033 | H19: =(1-C18)*(1-C20) -> 0.66666698 | I19: =-(1-C18)*(1+C20) -> -0.17863302 | J19: =-(1+C18)*(1+C20) -> -0.66666698 | K19: =(1+C18)*(1+C20) -> 0.66666698 | L19: =(1-C18)*(1+C20) -> 0.17863302 | N19: -4.976066 | O19: 40 | P19: -2.357267 | R19: =$F$3*N19 -> -0.62200826 | S19: =$F$3*O19 -> 5 | T19: =$F$3*P19 -> -0.29465837
B20: ζ | C20: -0.57735 | E20: =-(1-C18)*(1-C19) -> -0.17863302 | F20: =-(1+C18)*(1-C19) -> -0.66666698 | G20: =-(1+C18)*(1+C19) -> -2.488033 | H20: =-(1-C18)*(1+C19) -> -0.66666698 | I20: =(1-C18)*(1-C19) -> 0.17863302 | J20: =(1+C18)*(1-C19) -> 0.66666698 | K20: =(1+C18)*(1+C19) -> 2.488033 | L20: =(1-C18)*(1+C19) -> 0.66666698 | N20: -1.333334 | O20: 0 | P20: 32.893167 | R20: =$F$3*N20 -> -0.16666674 | S20: =$F$3*O20 -> 0 | T20: =$F$3*P20 -> 4.1116459
A22: 3 | B22: ξ | C22: 0.57735 | E22: =-(1-C23)*(1-C24) -> -0.66666698 | F22: =(1-C23)*(1-C24) -> 0.66666698 | G22: =(1+C23)*(1-C24) -> 0.17863302 | H22: =-(1+C23)*(1-C24) -> -0.17863302 | I22: =-(1-C23)*(1+C24) -> -2.488033 | J22: =(1-C23)*(1+C24) -> 2.488033 | K22: =(1+C23)*(1+C24) -> 0.66666698 | L22: =-(1+C23)*(1+C24) -> -0.66666698 | N22: {=MMULT(E22:L24,$B$3:$D$10)} -> 41.333334 | O22: 0 | P22: -6.976067 | R22: =$F$3*N22 -> 5.1666667 | S22: =$F$3*O22 -> 0 | T22: =$F$3*P22 -> -0.87200837 | V22: =MDETERM(R22:T24) -> 124.30191
B23: η | C23: -0.57735 | E23: =-(1-C22)*(1-C24) -> -0.17863302 | F23: =-(1+C22)*(1-C24) -> -0.66666698 | G23: =(1+C22)*(1-C24) -> 0.66666698 | H23: =(1-C22)*(1-C24) -> 0.17863302 | I23: =-(1-C22)*(1+C24) -> -0.66666698 | J23: =-(1+C22)*(1+C24) -> -2.488033 | K23: =(1+C22)*(1+C24) -> 2.488033 | L23: =(1-C22)*(1+C24) -> 0.66666698 | N23: -1.333334 | O23: 40 | P23: -8.797433 | R23: =$F$3*N23 -> -0.16666674 | S23: =$F$3*O23 -> 5 | T23: =$F$3*P23 -> -1.0996791
B24: ζ | C24: 0.57735 | E24: =-(1-C22)*(1-C23) -> -0.66666698 | F24: =-(1+C22)*(1-C23) -> -2.488033 | G24: =-(1+C22)*(1+C23) -> -0.66666698 | H24: =-(1-C22)*(1+C23) -> -0.17863302 | I24: =(1-C22)*(1-C23) -> 0.66666698 | J24: =(1+C22)*(1-C23) -> 2.488033 | K24: =(1+C22)*(1+C23) -> 0.66666698 | L24: =(1-C22)*(1+C23) -> 0.17863302 | N24: -4.976066 | O24: -4.4408921e-16 | P24: 39.333333 | R24: =$F$3*N24 -> -0.62200826 | S24: =$F$3*O24 -> -5.5511151e-17 | T24: =$F$3*P24 -> 4.9166666
A26: 4 | B26: ξ | C26: 0.57735 | E26: =-(1-C27)*(1-C28) -> -2.488033 | F26: =(1-C27)*(1-C28) -> 2.488033 | G26: =(1+C27)*(1-C28) -> 0.66666698 | H26: =-(1+C27)*(1-C28) -> -0.66666698 | I26: =-(1-C27)*(1+C28) -> -0.66666698 | J26: =(1-C27)*(1+C28) -> 0.66666698 | K26: =(1+C27)*(1+C28) -> 0.17863302 | L26: =-(1+C27)*(1+C28) -> -0.17863302 | N26: {=MMULT(E26:L28,$B$3:$D$10)} -> 44.976066 | O26: 0 | P26: -1.869233 | R26: =$F$3*N26 -> 5.6220083 | S26: =$F$3*O26 -> 0 | T26: =$F$3*P26 -> -0.23365413 | V26: =MDETERM(R26:T28) -> 137.48103
B27: η | C27: -0.57735 | E27: =-(1-C26)*(1-C28) -> -0.66666698 | F27: =-(1+C26)*(1-C28) -> -2.488033 | G27: =(1+C26)*(1-C28) -> 2.488033 | H27: =(1-C26)*(1-C28) -> 0.66666698 | I27: =-(1-C26)*(1+C28) -> -0.17863302 | J27: =-(1+C26)*(1+C28) -> -0.66666698 | K27: =(1+C26)*(1+C28) -> 0.66666698 | L27: =(1-C26)*(1+C28) -> 0.17863302 | N27: -4.976066 | O27: 40 | P27: -2.357267 | R27: =$F$3*N27 -> -0.62200826 | S27: =$F$3*O27 -> 5 | T27: =$F$3*P27 -> -0.29465837
B28: ζ | C28: -0.57735 | E28: =-(1-C26)*(1-C27) -> -0.66666698 | F28: =-(1+C26)*(1-C27) -> -2.488033 | G28: =-(1+C26)*(1+C27) -> -0.66666698 | H28: =-(1-C26)*(1+C27) -> -0.17863302 | I28: =(1-C26)*(1-C27) -> 0.66666698 | J28: =(1+C26)*(1-C27) -> 2.488033 | K28: =(1+C26)*(1+C27) -> 0.66666698 | L28: =(1-C26)*(1+C27) -> 0.17863302 | N28: -4.976066 | O28: -4.4408921e-16 | P28: 39.333333 | R28: =$F$3*N28 -> -0.62200826 | S28: =$F$3*O28 -> -5.5511151e-17 | T28: =$F$3*P28 -> 4.9166666
A30: 5 | B30: ξ | C30: -0.57735 | E30: =-(1-C31)*(1-C32) -> -0.17863302 | F30: =(1-C31)*(1-C32) -> 0.17863302 | G30: =(1+C31)*(1-C32) -> 0.66666698 | H30: =-(1+C31)*(1-C32) -> -0.66666698 | I30: =-(1-C31)*(1+C32) -> -0.66666698 | J30: =(1-C31)*(1+C32) -> 0.66666698 | K30: =(1+C31)*(1+C32) -> 2.488033 | L30: =-(1+C31)*(1+C32) -> -2.488033 | N30: {=MMULT(E30:L32,$B$3:$D$10)} -> 40.357266 | O30: 0 | P30: -8.797433 | R30: =$F$3*N30 -> 5.0446583 | S30: =$F$3*O30 -> 0 | T30: =$F$3*P30 -> -1.0996791 | V30: =MDETERM(R30:T32) -> 123.76897
B31: η | C31: 0.57735 | E31: =-(1-C30)*(1-C32) -> -0.66666698 | F31: =-(1+C30)*(1-C32) -> -0.17863302 | G31: =(1+C30)*(1-C32) -> 0.17863302 | H31: =(1-C30)*(1-C32) -> 0.66666698 | I31: =-(1-C30)*(1+C32) -> -2.488033 | J31: =-(1+C30)*(1+C32) -> -0.66666698 | K31: =(1+C30)*(1+C32) -> 0.66666698 | L31: =(1-C30)*(1+C32) -> 2.488033 | N31: -0.35726604 | O31: 40 | P31: -6.976067 | R31: =$F$3*N31 -> -0.044658256 | S31: =$F$3*O31 -> 5 | T31: =$F$3*P31 -> -0.87200837
B32: ζ | C32: 0.57735 | E32: =-(1-C30)*(1-C31) -> -0.66666698 | F32: =-(1+C30)*(1-C31) -> -0.17863302 | G32: =-(1+C30)*(1+C31) -> -0.66666698 | H32: =-(1-C30)*(1+C31) -> -2.488033 | I32: =(1-C30)*(1-C31) -> 0.66666698 | J32: =(1+C30)*(1-C31) -> 0.17863302 | K32: =(1+C30)*(1+C31) -> 0.66666698 | L32: =(1-C30)*(1+C31) -> 2.488033 | N32: -0.35726604 | O32: 0 | P32: 39.333333 | R32: =$F$3*N32 -> -0.044658256 | S32: =$F$3*O32 -> 0 | T32: =$F$3*P32 -> 4.9166666
A34: 6 | B34: ξ | C34: -0.57735 | E34: =-(1-C35)*(1-C36) -> -0.66666698 | F34: =(1-C35)*(1-C36) -> 0.66666698 | G34: =(1+C35)*(1-C36) -> 2.488033 | H34: =-(1+C35)*(1-C36) -> -2.488033 | I34: =-(1-C35)*(1+C36) -> -0.17863302 | J34: =(1-C35)*(1+C36) -> 0.17863302 | K34: =(1+C35)*(1+C36) -> 0.66666698 | L34: =-(1+C35)*(1+C36) -> -0.66666698 | N34: {=MMULT(E34:L36,$B$3:$D$10)} -> 41.333334 | O34: 0 | P34: -2.357267 | R34: =$F$3*N34 -> 5.1666667 | S34: =$F$3*O34 -> 0 | T34: =$F$3*P34 -> -0.29465837 | V34: =MDETERM(R34:T36) -> 126.9481
B35: η | C35: 0.57735 | E35: =-(1-C34)*(1-C36) -> -2.488033 | F35: =-(1+C34)*(1-C36) -> -0.66666698 | G35: =(1+C34)*(1-C36) -> 0.66666698 | H35: =(1-C34)*(1-C36) -> 2.488033 | I35: =-(1-C34)*(1+C36) -> -0.66666698 | J35: =-(1+C34)*(1+C36) -> -0.17863302 | K35: =(1+C34)*(1+C36) -> 0.17863302 | L35: =(1-C34)*(1+C36) -> 0.66666698 | N35: -1.333334 | O35: 40 | P35: -1.869233 | R35: =$F$3*N35 -> -0.16666674 | S35: =$F$3*O35 -> 5 | T35: =$F$3*P35 -> -0.23365413
B36: ζ | C36: -0.57735 | E36: =-(1-C34)*(1-C35) -> -0.66666698 | F36: =-(1+C34)*(1-C35) -> -0.17863302 | G36: =-(1+C34)*(1+C35) -> -0.66666698 | H36: =-(1-C34)*(1+C35) -> -2.488033 | I36: =(1-C34)*(1-C35) -> 0.66666698 | J36: =(1+C34)*(1-C35) -> 0.17863302 | K36: =(1+C34)*(1+C35) -> 0.66666698 | L36: =(1-C34)*(1+C35) -> 2.488033 | N36: -0.35726604 | O36: 0 | P36: 39.333333 | R36: =$F$3*N36 -> -0.044658256 | S36: =$F$3*O36 -> 0 | T36: =$F$3*P36 -> 4.9166666
A38: 7 | B38: ξ | C38: -0.57735 | E38: =-(1-C39)*(1-C40) -> -0.66666698 | F38: =(1-C39)*(1-C40) -> 0.66666698 | G38: =(1+C39)*(1-C40) -> 0.17863302 | H38: =-(1+C39)*(1-C40) -> -0.17863302 | I38: =-(1-C39)*(1+C40) -> -2.488033 | J38: =(1-C39)*(1+C40) -> 2.488033 | K38: =(1+C39)*(1+C40) -> 0.66666698 | L38: =-(1+C39)*(1+C40) -> -0.66666698 | N38: {=MMULT(E38:L40,$B$3:$D$10)} -> 41.333334 | O38: 0 | P38: -6.976067 | R38: =$F$3*N38 -> 5.1666667 | S38: =$F$3*O38 -> 0 | T38: =$F$3*P38 -> -0.87200837 | V38: =MDETERM(R38:T40) -> 142.77803
B39: η | C39: -0.57735 | E39: =-(1-C38)*(1-C40) -> -0.66666698 | F39: =-(1+C38)*(1-C40) -> -0.17863302 | G39: =(1+C38)*(1-C40) -> 0.17863302 | H39: =(1-C38)*(1-C40) -> 0.66666698 | I39: =-(1-C38)*(1+C40) -> -2.488033 | J39: =-(1+C38)*(1+C40) -> -0.66666698 | K39: =(1+C38)*(1+C40) -> 0.66666698 | L39: =(1-C38)*(1+C40) -> 2.488033 | N39: -0.35726604 | O39: 40 | P39: -6.976067 | R39: =$F$3*N39 -> -0.044658256 | S39: =$F$3*O39 -> 5 | T39: =$F$3*P39 -> -0.87200837
B40: ζ | C40: 0.57735 | E40: =-(1-C38)*(1-C39) -> -2.488033 | F40: =-(1+C38)*(1-C39) -> -0.66666698 | G40: =-(1+C38)*(1+C39) -> -0.17863302 | H40: =-(1-C38)*(1+C39) -> -0.66666698 | I40: =(1-C38)*(1-C39) -> 2.488033 | J40: =(1+C38)*(1-C39) -> 0.66666698 | K40: =(1+C38)*(1+C39) -> 0.17863302 | L40: =(1-C38)*(1+C39) -> 0.66666698 | N40: -1.333334 | O40: 0 | P40: 44.440167 | R40: =$F$3*N40 -> -0.16666674 | S40: =$F$3*O40 -> 0 | T40: =$F$3*P40 -> 5.5550209
A42: 8 | B42: ξ | C42: -0.57735 | E42: =-(1-C43)*(1-C44) -> -2.488033 | F42: =(1-C43)*(1-C44) -> 2.488033 | G42: =(1+C43)*(1-C44) -> 0.66666698 | H42: =-(1+C43)*(1-C44) -> -0.66666698 | I42: =-(1-C43)*(1+C44) -> -0.66666698 | J42: =(1-C43)*(1+C44) -> 0.66666698 | K42: =(1+C43)*(1+C44) -> 0.17863302 | L42: =-(1+C43)*(1+C44) -> -0.17863302 | N42: {=MMULT(E42:L44,$B$3:$D$10)} -> 44.976066 | O42: 0 | P42: -1.869233 | R42: =$F$3*N42 -> 5.6220083 | S42: =$F$3*O42 -> 0 | T42: =$F$3*P42 -> -0.23365413 | V42: =MDETERM(R42:T44) -> 155.95715
B43: η | C43: -0.57735 | E43: =-(1-C42)*(1-C44) -> -2.488033 | F43: =-(1+C42)*(1-C44) -> -0.66666698 | G43: =(1+C42)*(1-C44) -> 0.66666698 | H43: =(1-C42)*(1-C44) -> 2.488033 | I43: =-(1-C42)*(1+C44) -> -0.66666698 | J43: =-(1+C42)*(1+C44) -> -0.17863302 | K43: =(1+C42)*(1+C44) -> 0.17863302 | L43: =(1-C42)*(1+C44) -> 0.66666698 | N43: -1.333334 | O43: 40 | P43: -1.869233 | R43: =$F$3*N43 -> -0.16666674 | S43: =$F$3*O43 -> 5 | T43: =$F$3*P43 -> -0.23365413
B44: ζ | C44: -0.57735 | E44: =-(1-C42)*(1-C43) -> -2.488033 | F44: =-(1+C42)*(1-C43) -> -0.66666698 | G44: =-(1+C42)*(1+C43) -> -0.17863302 | H44: =-(1-C42)*(1+C43) -> -0.66666698 | I44: =(1-C42)*(1-C43) -> 2.488033 | J44: =(1+C42)*(1-C43) -> 0.66666698 | K44: =(1+C42)*(1+C43) -> 0.17863302 | L44: =(1-C42)*(1+C43) -> 0.66666698 | N44: -1.333334 | O44: 0 | P44: 44.440167 | R44: =$F$3*N44 -> -0.16666674 | S44: =$F$3*O44 -> 0 | T44: =$F$3*P44 -> 5.5550209
U46: V | V46: =SUM(V14:V44) -> 1020
B49: n | C49: ξi | D49: Hi
B50: 2 | C50: 0.57735 | D50: 1
C51: =-C50 -> -0.57735 | D51: 1
A53: 27 слагаемых
V54: det[J] | X54: det[J]*коэф | Z54: точки | AA54: вес
...

Sheet !V пенты через якобиан
F1: узлы с гексы
A2: точки | B2: X | C2: Y | D2: Z | F2: 1-2-4-5-6-8 | O2: 0 | P2: 0 | Q2: 0 | S2: 0 | T2: 0 | U2: 0 | W2: 0 | X2: 0 | Y2: 0
A3: 1 | B3: ='+V гексы'!B4 -> 0 | C3: ='+V гексы'!C4 -> 0 | D3: ='+V гексы'!D4 -> 0 | O3: 10 | P3: 0 | Q3: 0 | S3: 10 | T3: 0 | U3: 0 | W3: 10 | X3: 0 | Y3: 0
A4: 2 | B4: ='+V гексы'!B5 -> 12 | C4: ='+V гексы'!C5 -> 0 | D4: ='+V гексы'!D5 -> 0 | O4: 10 | P4: 5 | Q4: 0 | S4: 10 | T4: 5 | U4: 0 | W4: 10 | X4: 5 | Y4: 0
A5: 3 | B5: ='+V гексы'!B7 -> 0 | C5: ='+V гексы'!C7 -> 10 | D5: ='+V гексы'!D7 -> 0 | O5: -3 | P5: -5 | Q5: 10 | S5: 0 | T5: 0 | U5: 10 | W5: 0 | X5: 0 | Y5: 10
A6: 4 | B6: ='+V гексы'!B8 -> 0 | C6: ='+V гексы'!C8 -> 0 | D6: ='+V гексы'!D8 -> 12 | O6: -5 | P6: 5 | Q6: 10 | S6: 5 | T6: 0 | U6: 10 | W6: 12 | X6: 0 | Y6: 10
A7: 5 | B7: ='+V гексы'!B9 -> 10 | C7: ='+V гексы'!C9 -> 0 | D7: ='+V гексы'!D9 -> 10 | O7: -5 | P7: -5 | Q7: 10 | S7: -2 | T7: 5 | U7: 10 | W7: 10 | X7: 5 | Y7: 10
A8: 6 | B8: ='+V гексы'!B11 -> 0 | C8: ='+V гексы'!C11 -> 10 | D8: ='+V гексы'!D11 -> 10
O9: Jacobian Ratio | P9: =-3.7 -> -3.7 | S9: 1.47 | W9: 1.1
H20: Киселев, стр 110
A23: слагаемые | B23: ось | C23: координ. т. интегр. | E23: производные функции формы | L23: матрица Якоби | P23: det[J] | R23: det[J]*0,5
A24: 1 | B24: ξ | C24: =1/3 -> 0.33333333 | E24: =-(1-C26)/2 -> -0.2113 | F24: =(1-C26)/2 -> 0.2113 | G24: 0 | H24: =-(1+C26)/2 -> -0.7887 | I24: =(1+C26)/2 -> 0.7887 | J24: 0 | L24: {=MMULT(E24:J26,$B$3:$D$8)} -> 10.4226 | M24: 0 | N24: -1.5774 | P24: =MDETERM(L24:N26) -> 550.614 | R24: =0.5*P24 -> 275.307
B25: η | C25: =1/3 -> 0.33333333 | E25: =-(1-C26)/2 -> -0.2113 | F25: 0 | G25: =(1-C26)/2 -> 0.2113 | H25: =-(1+C26)/2 -> -0.7887 | I25: 0 | J25: =(1+C26)/2 -> 0.7887 | L25: 0 | M25: 10 | N25: -1.5774
B26: ζ | C26: 0.5774 | E26: =-0.5*(1-C24-C25) -> -0.16666667 | F26: =-0.5*C24 -> -0.16666667 | G26: =-0.5*C25 -> -0.16666667 | H26: =0.5*(1-C24-C25) -> 0.16666667 | I26: =0.5*C24 -> 0.16666667 | J26: =0.5*C25 -> 0.16666667 | L26: -0.33333333 | M26: 0 | N26: 5.3333333
A28: 2 | B28: ξ | C28: =1/3 -> 0.33333333 | E28: =-(1-C30)/2 -> -0.788675 | F28: =(1-C30)/2 -> 0.788675 | G28: 0 | H28: =-(1+C30)/2 -> -0.211325 | I28: =(1+C30)/2 -> 0.211325 | J28: 0 | L28: {=MMULT(E28:J30,$B$3:$D$8)} -> 11.57735 | M28: 0 | N28: -0.42265 | P28: =MDETERM(L28:N30) -> 616.04983 | R28: =P28*0.5 -> 308.02492
B29: η | C29: =1/3 -> 0.33333333 | E29: =-(1-C30)/2 -> -0.788675 | F29: 0 | G29: =(1-C30)/2 -> 0.788675 | H29: =-(1+C30)/2 -> -0.211325 | I29: 0 | J29: =(1+C30)/2 -> 0.211325 | L29: 0 | M29: 10 | N29: -0.42265
B30: ζ | C30: -0.57735 | E30: =-0.5*(1-C28-C29) -> -0.16666667 | F30: =-0.5*C28 -> -0.16666667 | G30: =-0.5*C29 -> -0.16666667 | H30: =0.5*(1-C28-C29) -> 0.16666667 | I30: =0.5*C28 -> 0.16666667 | J30: =0.5*C29 -> 0.16666667 | L30: -0.33333333 | M30: 0 | N30: 5.3333333
Q31: V | R31: =SUM(R24:R30) -> 583.33192
Q35: Jacobian Ratio | R35: =R24/R28 -> 0.89378159
Q36: Jacobian Ratio | R36: =R28/R24 -> 1.1188416
A37: одна точка
A38: слагаемые | B38: ось | C38: координ. т. интегр. | E38: производные функции формы | L38: матрица Якоби | P38: det[J]
A39: 1 | B39: ξ | C39: =1/3 -> 0.33333333 | E39: =-(1-C41)/2 -> -0.5 | F39: =(1-C41)/2 -> 0.5 | G39: 0 | H39: =-(1+C41)/2 -> -0.5 | I39: =(1+C41)/2 -> 0.5 | J39: 0 | L39: {=MMULT(E39:J41,$B$3:$D$8)} -> 11 | M39: 0 | N39: -1 | P39: =MDETERM(L39:N41) -> 583.33333 | R39: =P39*2*0.5 -> 583.33333
B40: η | C40: =1/3 -> 0.33333333 | E40: =-(1-C41)/2 -> -0.5 | F40: 0 | G40: =(1-C41)/2 -> 0.5 | H40: =-(1+C41)/2 -> -0.5 | I40: 0 | J40: =(1+C41)/2 -> 0.5 | L40: 0 | M40: 10 | N40: -1
B41: ζ | C41: 0 | E41: =-0.5*(1-C39-C40) -> -0.16666667 | F41: =-0.5*C39 -> -0.16666667 | G41: =-0.5*C40 -> -0.16666667 | H41: =0.5*(1-C39-C40) -> 0.16666667 | I41: =0.5*C39 -> 0.16666667 | J41: =0.5*C40 -> 0.16666667 | L41: -0.33333333 | M41: 0 | N41: 5.3333333

Sheet лок в гл и обр
B2: x | C2: y | D2: z | F2: коэф | H2: точки интегрирования
A3: 1 | B3: ='+NTNdetJ для гексы'!B4 -> 0 | C3: ='+NTNdetJ для гексы'!C4 -> 0 | D3: ='+NTNdetJ для гексы'!D4 -> 0 | F3: =1/8 -> 0.125 | H3: 0.57735
A4: 2 | B4: ='+NTNdetJ для гексы'!B5 -> 12 | C4: ='+NTNdetJ для гексы'!C5 -> 0 | D4: ='+NTNdetJ для гексы'!D5 -> 0 | H4: =-H3 -> -0.57735
A5: 3 | B5: ='+NTNdetJ для гексы'!B6 -> 10 | C5: ='+NTNdetJ для гексы'!C6 -> 10 | D5: ='+NTNdetJ для гексы'!D6 -> 0
A6: 4 | B6: ='+NTNdetJ для гексы'!B7 -> 0 | C6: ='+NTNdetJ для гексы'!C7 -> 10 | D6: ='+NTNdetJ для гексы'!D7 -> 0
A7: 5 | B7: ='+NTNdetJ для гексы'!B8 -> 0 | C7: ='+NTNdetJ для гексы'!C8 -> 0 | D7: ='+NTNdetJ для гексы'!D8 -> 12
A8: 6 | B8: ='+NTNdetJ для гексы'!B9 -> 10 | C8: ='+NTNdetJ для гексы'!C9 -> 0 | D8: ='+NTNdetJ для гексы'!D9 -> 10
A9: 7 | B9: ='+NTNdetJ для гексы'!B10 -> 10 | C9: ='+NTNdetJ для гексы'!C10 -> 10 | D9: ='+NTNdetJ для гексы'!D10 -> 7
A10: 8 | B10: ='+NTNdetJ для гексы'!B11 -> 0 | C10: ='+NTNdetJ для гексы'!C11 -> 10 | D10: ='+NTNdetJ для гексы'!D11 -> 10
W12: =W14+W29+W44+W59+W74+W89+W104+W119 -> 846.5625
A13: слагаемые | B13: ось | C13: координата т. интегр. | E13: производные функции формы | N13: матрица Якоби (без коэффициента 1/8) | R13: матрица Якоби | V13: det[J] | W13: det[J]* коэф | X13: коэф2
A14: 1 | B14: ξ | C14: 0.5 | E14: =-(1-C15)*(1-C16) -> -0.25 | F14: =(1-C15)*(1-C16) -> 0.25 | G14: =(1+C15)*(1-C16) -> 0.75 | H14: =-(1+C15)*(1-C16) -> -0.75 | I14: =-(1-C15)*(1+C16) -> -0.75 | J14: =(1-C15)*(1+C16) -> 0.75 | K14: =(1+C15)*(1+C16) -> 2.25 | L14: =-(1+C15)*(1+C16) -> -2.25 | N14: {=MMULT(E14:L16,$B$3:$D$10)} -> 40.5 | O14: 0 | P14: -8.25 | R14: =$F$3*N14 -> 5.0625 | S14: =$F$3*O14 -> 0 | T14: =$F$3*P14 -> -1.03125 | V14: =MDETERM(R14:T16) -> 105.82031 | W14: =V14*X14 -> 846.5625 | X14: 8
B15: η | C15: 0.5 | E15: =-(1-C14)*(1-C16) -> -0.25 | F15: =-(1+C14)*(1-C16) -> -0.75 | G15: =(1+C14)*(1-C16) -> 0.75 | H15: =(1-C14)*(1-C16) -> 0.25 | I15: =-(1-C14)*(1+C16) -> -0.75 | J15: =-(1+C14)*(1+C16) -> -2.25 | K15: =(1+C14)*(1+C16) -> 2.25 | L15: =(1-C14)*(1+C16) -> 0.75 | N15: -1.5 | O15: 40 | P15: -8.25 | R15: =$F$3*N15 -> -0.1875 | S15: =$F$3*O15 -> 5 | T15: =$F$3*P15 -> -1.03125
B16: ζ | C16: 0.5 | E16: =-(1-C14)*(1-C15) -> -0.25 | F16: =-(1+C14)*(1-C15) -> -0.75 | G16: =-(1+C14)*(1+C15) -> -2.25 | H16: =-(1-C14)*(1+C15) -> -0.75 | I16: =(1-C14)*(1-C15) -> 0.25 | J16: =(1+C14)*(1-C15) -> 0.75 | K16: =(1+C14)*(1+C15) -> 2.25 | L16: =(1-C14)*(1+C15) -> 0.75 | N16: -1.5 | O16: 0 | P16: 33.75 | R16: =$F$3*N16 -> -0.1875 | S16: =$F$3*O16 -> 0 | T16: =$F$3*P16 -> 4.21875
E18: N1 | F18: N2 | G18: N3 | H18: N4 | I18: N5 | J18: N6 | K18: N7 | L18: N8
E19: =(1-C14)*(1-C15)*(1-C16)/8 -> 0.015625 | F19: =(1+C14)*(1-C15)*(1-C16)/8 -> 0.046875 | G19: =(1+C14)*(1+C15)*(1-C16)/8 -> 0.140625 | H19: =(1-C14)*(1+C15)*(1-C16)/8 -> 0.046875 | I19: =(1-C14)*(1-C15)*(1+C16)/8 -> 0.046875 | J19: =(1+C14)*(1-C15)*(1+C16)/8 -> 0.140625 | K19: =(1+C14)*(1+C15)*(1+C16)/8 -> 0.421875 | L19: =(1-C14)*(1+C15)*(1+C16)/8 -> 0.140625
A22: точку из лок в глобальные
A24: X | B24: {=MMULT($E$19:$L$19,B3:B10)} -> 7.59375
A25: Y | B25: {=MMULT($E$19:$L$19,C3:C10)} -> 7.5
A26: Z | B26: =MMULT($E$19:$L$19,D3:D10) -> 6.328125
A28: N | O28: I | S28: M
A29: 0 | C29: {=TRANSPOSE(A29:A31)} -> 0 | D29: 0 | E29: -1 | G29: {=MMULT(A29:A31,C29:E29)} -> 0 | H29: 0 | I29: 0 | K29: =G29*2 -> 0 | L29: =H29*2 -> 0 | M29: =I29*2 -> 0 | O29: 1 | S29: =O29-K29 -> 1 | T29: =P29-L29 -> 0 | U29: =Q29-M29 -> 0
A30: 0 | G30: 0 | H30: 0 | I30: 0 | K30: =G30*2 -> 0 | L30: =H30*2 -> 0 | M30: =I30*2 -> 0 | P30: 1 | S30: =O30-K30 -> 0 | T30: =P30-L30 -> 1 | U30: =Q30-M30 -> 0
A31: -1 | G31: 0 | H31: 0 | I31: 1 | K31: =G31*2 -> 0 | L31: =H31*2 -> 0 | M31: =I31*2 -> 2 | Q31: 1 | S31: =O31-K31 -> 0 | T31: =P31-L31 -> 0 | U31: =Q31-M31 -> -1

Sheet частн произв в гл коор для пент
A2: пента с 1 точкой интегрирования
A4: найдем частные производные в 1 точке интегрирования
A6: x | B6: y | C6: z
A7: ='!V пенты через якобиан'!B3 -> 0 | B7: ='!V пенты через якобиан'!C3 -> 0 | C7: ='!V пенты через якобиан'!D3 -> 0
A8: ='!V пенты через якобиан'!B4 -> 12 | B8: ='!V пенты через якобиан'!C4 -> 0 | C8: ='!V пенты через якобиан'!D4 -> 0
A9: ='!V пенты через якобиан'!B5 -> 0 | B9: ='!V пенты через якобиан'!C5 -> 10 | C9: ='!V пенты через якобиан'!D5 -> 0
A10: ='!V пенты через якобиан'!B6 -> 0 | B10: ='!V пенты через якобиан'!C6 -> 0 | C10: ='!V пенты через якобиан'!D6 -> 12
A11: ='!V пенты через якобиан'!B7 -> 10 | B11: ='!V пенты через якобиан'!C7 -> 0 | C11: ='!V пенты через якобиан'!D7 -> 10
A12: ='!V пенты через якобиан'!B8 -> 0 | B12: ='!V пенты через якобиан'!C8 -> 10 | C12: ='!V пенты через якобиан'!D8 -> 10
D24: N1 | E24: N2 | F24: N3 | G24: N4 | H24: N5 | I24: N6
A25: ось | B25: координата т. интегр. | D25: производные функции формы dNi/dξ, dNi/dη, dNi/dζ | K25: матрица Якоби [J] | O25: {J]-1 | S25: det[J] (по формуле) | U25: det[J] | V25: коэф | W25: =2*0.5 -> 1
A26: ξ | B26: =1/3 -> 0.33333333 | D26: =-(1-B28)/2 -> -0.5 | E26: =(1-B28)/2 -> 0.5 | F26: 0 | G26: =-(1+B28)/2 -> -0.5 | H26: =(1+B28)/2 -> 0.5 | I26: 0 | K26: {=MMULT(D26:I28,A7:C12)} -> 11 | L26: 0 | M26: -1 | O26: {=MINVERSE(K26:M28)} -> 0.091428571 | P26: 0 | Q26: 0.017142857 | S26: =K26*L27*M28+L26*M27*K28+K27*L28*M26-M26*L27*K28-L28*M27*K26-K27*L26*M28 -> 583.33333 | U26: =MDETERM(K26:M28) -> 583.33333 | W26: =U26*W25 -> 583.33333
A27: η | B27: =1/3 -> 0.33333333 | D27: =-(1-B28)/2 -> -0.5 | E27: 0 | F27: =(1-B28)/2 -> 0.5 | G27: =-(1+B28)/2 -> -0.5 | H27: 0 | I27: =(1+B28)/2 -> 0.5 | K27: 0 | L27: 10 | M27: -1 | O27: 0.00057142857 | P27: 0.1 | Q27: 0.018857143
A28: ζ | B28: 0 | D28: =-0.5*(1-B26-B27) -> -0.16666667 | E28: =-0.5*B26 -> -0.16666667 | F28: =-0.5*B27 -> -0.16666667 | G28: =0.5*(1-B26-B27) -> 0.16666667 | H28: =0.5*B26 -> 0.16666667 | I28: =0.5*B27 -> 0.16666667 | K28: -0.33333333 | L28: 0 | M28: 5.3333333 | O28: 0.0057142857 | P28: 0 | Q28: 0.18857143
D29: B | K29: BT | O29: BT*B | V29: BT*B*det[J]*коэф
A30: dNi/dx | D30: {=MMULT($O$26:$Q$28,D26:D28)} -> -0.048571429 | E30: {=MMULT($O$26:$Q$28,E26:E28)} -> 0.042857143 | F30: {=MMULT($O$26:$Q$28,F26:F28)} -> -0.0028571429 | G30: {=MMULT($O$26:$Q$28,G26:G28)} -> -0.042857143 | H30: {=MMULT($O$26:$Q$28,H26:H28)} -> 0.048571429 | I30: {=MMULT($O$26:$Q$28,I26:I28)} -> 0.0028571429 | K30: {=TRANSPOSE(D30:I32)} -> -0.048571429 | L30: -0.053428571 | M30: -0.034285714 | O30: {=MMULT(K30:M35,D30:I32)} -> 0.0063893061 | P30: -0.00094938776 | Q30: -0.0012871837 | R30: 0.0036208163 | S30: -0.0037178776 | T30: -0.0040556735 | V30: =O30*$W$26 -> 3.7270952 | W30: =P30*$W$26 -> -0.55380952 | X30: =Q30*$W$26 -> -0.75085714 | Y30: =R30*$W$26 -> 2.1121429 | Z30: =S30*$W$26 -> -2.1687619 | AA30: =T30*$W$26 -> -2.3658095
A31: dNi/dy | D31: -0.053428571 | E31: -0.0028571429 | F31: 0.046857143 | G31: -0.047142857 | H31: 0.0034285714 | I31: 0.053142857 | K31: 0.042857143 | L31: -0.0028571429 | M31: -0.028571429 | O31: -0.00094938776 | P31: 0.0026612245 | Q31: 0.00064163265 | R31: -0.0025183673 | S31: 0.0010922449 | T31: -0.00092734694 | V31: =O31*$W$26 -> -0.55380952 | W31: =P31*$W$26 -> 1.552381 | X31: =Q31*$W$26 -> 0.37428571 | Y31: =R31*$W$26 -> -1.4690476 | Z31: =S31*$W$26 -> 0.63714286 | AA31: =T31*$W$26 -> -0.54095238
A32: dNi/dz | D32: -0.034285714 | E32: -0.028571429 | F32: -0.031428571 | G32: 0.028571429 | H32: 0.034285714 | I32: 0.031428571 | K32: -0.0028571429 | L32: 0.046857143 | M32: -0.031428571 | O32: -0.0012871837 | P32: 0.00064163265 | Q32: 0.0031915102 | R32: -0.0029844898 | S32: -0.0010556735 | T32: 0.0014942041 | V32: =O32*$W$26 -> -0.75085714 | W32: =P32*$W$26 -> 0.37428571 | X32: =Q32*$W$26 -> 1.8617143 | Y32: =R32*$W$26 -> -1.7409524 | Z32: =S32*$W$26 -> -0.61580952 | AA32: =T32*$W$26 -> 0.87161905
K33: -0.042857143 | L33: -0.047142857 | M33: 0.028571429 | O33: 0.0036208163 | P33: -0.0025183673 | Q33: -0.0029844898 | R33: 0.0048755102 | S33: -0.0012636735 | T33: -0.0017297959 | V33: =O33*$W$26 -> 2.1121429 | W33: =P33*$W$26 -> -1.4690476 | X33: =Q33*$W$26 -> -1.7409524 | Y33: =R33*$W$26 -> 2.8440476 | Z33: =S33*$W$26 -> -0.73714286 | AA33: =T33*$W$26 -> -1.0090476
K34: 0.048571429 | L34: 0.0034285714 | M34: 0.034285714 | O34: -0.0037178776 | P34: 0.0010922449 | Q34: -0.0010556735 | R34: -0.0012636735 | S34: 0.003546449 | T34: 0.0013985306 | V34: =O34*$W$26 -> -2.1687619 | W34: =P34*$W$26 -> 0.63714286 | X34: =Q34*$W$26 -> -0.61580952 | Y34: =R34*$W$26 -> -0.73714286 | Z34: =S34*$W$26 -> 2.0687619 | AA34: =T34*$W$26 -> 0.81580952
K35: 0.0028571429 | L35: 0.053142857 | M35: 0.031428571 | O35: -0.0040556735 | P35: -0.00092734694 | Q35: 0.0014942041 | R35: -0.0017297959 | S35: 0.0013985306 | T35: 0.0038200816 | V35: =O35*$W$26 -> -2.3658095 | W35: =P35*$W$26 -> -0.54095238 | X35: =Q35*$W$26 -> 0.87161905 | Y35: =R35*$W$26 -> -1.0090476 | Z35: =S35*$W$26 -> 0.81580952 | AA35: =T35*$W$26 -> 2.228381
B48: матрица миноров | F48: матрица алгебраич дополнений | J48: транспонированная матрица | N48: {J]-1
B49: =L27*M28-M27*L28 -> 53.333333 | C49: =K27*M28-M27*K28 -> -0.33333333 | D49: =K27*L28-L27*K28 -> 3.3333333 | F49: =B49 -> 53.333333 | G49: =-C49 -> 0.33333333 | H49: =D49 -> 3.3333333 | J49: {=TRANSPOSE(F49:H51)} -> 53.333333 | K49: 0 | L49: 10 | N49: =J49/$U$26 -> 0.091428571 | O49: =K49/$U$26 -> 0 | P49: =L49/$U$26 -> 0.017142857
B50: =L26*M28-M26*L28 -> 0 | C50: =K26*M28-M26*K28 -> 58.333333 | D50: =K26*L28-L26*K28 -> 0 | F50: =-B50 -> 0 | G50: =C50 -> 58.333333 | H50: =-D50 -> 0 | J50: 0.33333333 | K50: 58.333333 | L50: 11 | N50: =J50/$U$26 -> 0.00057142857 | O50: =K50/$U$26 -> 0.1 | P50: =L50/$U$26 -> 0.018857143
B51: =L26*M27-M26*L27 -> 10 | C51: =K26*M27-M26*K27 -> -11 | D51: =K26*L27-L26*K27 -> 110 | F51: =B51 -> 10 | G51: =-C51 -> 11 | H51: =D51 -> 110 | J51: 3.3333333 | K51: 0 | L51: 110 | N51: =J51/$U$26 -> 0.0057142857 | O51: =K51/$U$26 -> 0 | P51: =L51/$U$26 -> 0.18857143
A54: две точки интегрирования
D56: N1 | E56: N2 | F56: N3 | G56: N4 | H56: N5 | I56: N6
A57: ось | B57: координата т. интегр. | D57: производные функции формы dNi/dξ, dNi/dη, dNi/dζ | K57: матрица Якоби [J] | O57: {J]-1 | S57: det[J] (по формуле) | U57: det[J] | V57: коэф | W57: =0.5*1 -> 0.5
A58: ξ | B58: =1/3 -> 0.33333333 | D58: =-(1-B60)/2 -> -0.2113 | E58: =(1-B60)/2 -> 0.2113 | F58: 0 | G58: =-(1+B60)/2 -> -0.7887 | H58: =(1+B60)/2 -> 0.7887 | I58: 0 | K58: {=MMULT(D58:I60,A7:C12)} -> 10.4226 | L58: 0 | M58: -1.5774 | O58: {=MINVERSE(K58:M60)} -> 0.096861564 | P58: 0 | Q58: 0.028648018 | S58: =K58*L59*M60+L58*M59*K60+K59*L60*M58-M58*L59*K60-L60*M59*K58-K59*L58*M60 -> 550.614 | U58: =MDETERM(K58:M60) -> 550.614 | W58: =W57*U58 -> 275.307
A59: η | B59: =1/3 -> 0.33333333 | D59: =-(1-B60)/2 -> -0.2113 | E59: 0 | F59: =(1-B60)/2 -> 0.2113 | G59: =-(1+B60)/2 -> -0.7887 | H59: 0 | I59: =(1+B60)/2 -> 0.7887 | K59: 0 | L59: 10 | M59: -1.5774 | O59: 0.00095493395 | P59: 0.1 | Q59: 0.029858684
A60: ζ | B60: 0.5774 | D60: =-0.5*(1-B58-B59) -> -0.16666667 | E60: =-0.5*B58 -> -0.16666667 | F60: =-0.5*B59 -> -0.16666667 | G60: =0.5*(1-B58-B59) -> 0.16666667 | H60: =0.5*B58 -> 0.16666667 | I60: =0.5*B59 -> 0.16666667 | K60: -0.33333333 | L60: 0 | M60: 5.3333333 | O60: 0.0060538478 | P60: 0 | Q60: 0.1892905
D61: B | K61: BT | O61: BT*B | V61: BT*B*det[J]*коэы
A62: dNi/dx | D62: {=MMULT($O$58:$Q$60,D58:D60)} -> -0.025241518 | E62: {=MMULT($O$58:$Q$60,E58:E60)} -> 0.015692179 | F62: {=MMULT($O$58:$Q$60,F58:F60)} -> -0.0047746697 | G62: {=MMULT($O$58:$Q$60,G58:G60)} -> -0.071620046 | H62: {=MMULT($O$58:$Q$60,H58:H60)} -> 0.081169385 | I62: {=MMULT($O$58:$Q$60,I58:I60)} -> 0.0047746697 | K62: {=TRANSPOSE(D62:I64)} -> -0.025241518 | L62: -0.026308225 | M62: -0.032827595 | O62: {=MMULT(K62:M67,D62:I64)} -> 0.0024069079 | P62: 0.00072318498 | Q62: 0.00073120726 | R62: 0.0028927034 | S62: -0.0033919738 | T62: -0.0033620297 | V62: =O62*$W$58 -> 0.6626386 | W62: =P62*$W$58 -> 0.19909789 | X62: =Q62*$W$58 -> 0.20130648 | Y62: =R62*$W$58 -> 0.79638149 | Z62: =S62*$W$58 -> -0.93383413 | AA62: =T62*$W$58 -> -0.92559032
A63: dNi/dy | D63: -0.026308225 | E63: -0.0047746697 | F63: 0.016153553 | G63: -0.074646709 | H63: 0.0057296037 | I63: 0.083846447 | K63: 0.015692179 | L63: -0.0047746697 | M63: -0.030269239 | O63: 0.00072318498 | P63: 0.0011852688 | Q63: 0.00080289371 | R63: -0.0015778821 | S63: 0.00014689536 | T63: -0.0012803607 | V63: =O63*$W$58 -> 0.19909789 | W63: =P63*$W$58 -> 0.32631279 | X63: =Q63*$W$58 -> 0.22104226 | Y63: =R63*$W$58 -> -0.434402 | Z63: =S63*$W$58 -> 0.040441321 | AA63: =T63*$W$58 -> -0.35249226
A64: dNi/dz | D64: -0.032827595 | E64: -0.030269239 | F64: -0.031548417 | G64: 0.026773747 | H64: 0.036323087 | I64: 0.031548417 | K64: -0.0047746697 | L64: 0.016153553 | M64: -0.031548417 | O64: 0.00073120726 | P64: 0.00080289371 | Q64: 0.0012790373 | R64: -0.0017085168 | S64: -0.0014409394 | T64: 0.00033631793 | V64: =O64*$W$58 -> 0.20130648 | W64: =P64*$W$58 -> 0.22104226 | X64: =Q64*$W$58 -> 0.35212793 | Y64: =R64*$W$58 -> -0.47036664 | Z64: =S64*$W$58 -> -0.39670071 | AA64: =T64*$W$58 -> 0.09259068
K65: -0.071620046 | L65: -0.074646709 | M65: 0.026773747 | O65: 0.0028927034 | P65: -0.0015778821 | Q65: -0.0017085168 | R65: 0.011418396 | S65: -0.005268546 | T65: -0.0057561541 | V65: =O65*$W$58 -> 0.79638149 | W65: =P65*$W$58 -> -0.434402 | X65: =Q65*$W$58 -> -0.47036664 | Y65: =R65*$W$58 -> 3.1435643 | Z65: =S65*$W$58 -> -1.4504676 | AA65: =T65*$W$58 -> -1.5847095
K66: 0.081169385 | L66: 0.0057296037 | M66: 0.036323087 | O66: -0.0033919738 | P66: 0.00014689536 | Q66: -0.0014409394 | R66: -0.005268546 | S66: 0.0079406641 | T66: 0.0020138998 | V66: =O66*$W$58 -> -0.93383413 | W66: =P66*$W$58 -> 0.040441321 | X66: =Q66*$W$58 -> -0.39670071 | Y66: =R66*$W$58 -> -1.4504676 | Z66: =S66*$W$58 -> 2.1861204 | AA66: =T66*$W$58 -> 0.55444071
K67: 0.0047746697 | L67: 0.083846447 | M67: 0.031548417 | O67: -0.0033620297 | P67: -0.0012803607 | Q67: 0.00033631793 | R67: -0.0057561541 | S67: 0.0020138998 | T67: 0.0080483268 | V67: =O67*$W$58 -> -0.92559032 | W67: =P67*$W$58 -> -0.35249226 | X67: =Q67*$W$58 -> 0.09259068 | Y67: =R67*$W$58 -> -1.5847095 | Z67: =S67*$W$58 -> 0.55444071 | AA67: =T67*$W$58 -> 2.2157607
D73: N1 | E73: N2 | F73: N3 | G73: N4 | H73: N5 | I73: N6
A74: ось | B74: координата т. интегр. | D74: производные функции формы dNi/dξ, dNi/dη, dNi/dζ | K74: матрица Якоби [J] | O74: {J]-1 | S74: det[J] (по формуле) | U74: det[J]
...

Sheet пример на стр 301 (частн произв
H1: X | I1: Y
A2: запишем производгые функции формы в локльных координатах | H2: 10 | I2: 10
H3: 20 | I3: 15
A4: подставляем значение точки в лок координтаъ | H4: 25 | I4: 30
H5: 8 | I5: 25
A6: находим мвтрицу J и обратную ей
A8: найдем значение произв a форм в лок точке
A10: ось | B10: координата т. интегр. | D10: производные функции формы dNi/dξ, dNi/dη | I10: матрица Якоби [J] | L10: {J]-1 | O10: det[J] | Q10: коэф | R10: det[J] *коэф
A11: ξ | B11: 0.5 | D11: =-(1-B12)/4 -> -0.125 | E11: =(1-B12)/4 -> 0.125 | F11: =(1+B12)/4 -> 0.375 | G11: =-(1+B12)/4 -> -0.375 | I11: {=MMULT(D11:G12,H2:I5)} -> 7.625 | J11: 2.5 | L11: {=MINVERSE(I11:J12)} -> 0.14117647 | M11: -0.047058824 | O11: =MDETERM(I11:J12) -> 53.125 | Q11: 1 | R11: =Q11*O11 -> 53.125
A12: η | B12: 0.5 | D12: =-(1-B11)/4 -> -0.125 | E12: =-(1+B11)/4 -> -0.375 | F12: =(1+B11)/4 -> 0.375 | G12: =(1-B11)/4 -> 0.125 | I12: 1.625 | J12: 7.5 | L12: -0.030588235 | M12: 0.14352941
D14: dNi/dξ, dNi/dη
D15: =(1-B12)*(2*B11+B12)/4 -> 0.1875
D16: =(1-B11)*(2*B12+B11)/4 -> 0.1875
F17: дельта
C18: dN1/dx | D18: {=MMULT(L11:M12,D15:D16)} -> 0.017647059 | E18: =15/850 -> 0.017647059 | F18: =D18-E18 -> 0
C19: dN1/dy | D19: 0.021176471 | E19: =18/850 -> 0.021176471 | F19: =D19-E19 -> 0

Sheet +NTNdetJ для пенты
A2: x | B2: y | C2: z
A3: ='!V пенты через якобиан'!B3 -> 0 | B3: ='!V пенты через якобиан'!C3 -> 0 | C3: ='!V пенты через якобиан'!D3 -> 0
A4: ='!V пенты через якобиан'!B4 -> 12 | B4: ='!V пенты через якобиан'!C4 -> 0 | C4: ='!V пенты через якобиан'!D4 -> 0
A5: ='!V пенты через якобиан'!B5 -> 0 | B5: ='!V пенты через якобиан'!C5 -> 10 | C5: ='!V пенты через якобиан'!D5 -> 0
A6: ='!V пенты через якобиан'!B6 -> 0 | B6: ='!V пенты через якобиан'!C6 -> 0 | C6: ='!V пенты через якобиан'!D6 -> 12
A7: ='!V пенты через якобиан'!B7 -> 10 | B7: ='!V пенты через якобиан'!C7 -> 0 | C7: ='!V пенты через якобиан'!D7 -> 10
A8: ='!V пенты через якобиан'!B8 -> 0 | B8: ='!V пенты через якобиан'!C8 -> 10 | C8: ='!V пенты через якобиан'!D8 -> 10
A19: одна точка интегрирования | K19: веса для треугольника на стр 280 Сегерлинда
A21: ось | B21: координата т. интегр. | D21: производные функции формы dNi/dξ, dNi/dη, dNi/dζ | K21: матрица Якоби [J] | O21: detJ | Q21: detJ* коэф
A22: ξ | B22: =1/3 -> 0.33333333 | D22: =-(1-B24)/2 -> -0.5 | E22: =(1-B24)/2 -> 0.5 | F22: 0 | G22: =-(1+B24)/2 -> -0.5 | H22: =(1+B24)/2 -> 0.5 | I22: 0 | K22: {=MMULT(D22:I24,A3:C8)} -> 11 | L22: 0 | M22: -1 | O22: =MDETERM(K22:M24) -> 583.33333 | Q22: =O22*2*0.5 -> 583.33333
A23: η | B23: =1/3 -> 0.33333333 | D23: =-(1-B24)/2 -> -0.5 | E23: 0 | F23: =(1-B24)/2 -> 0.5 | G23: =-(1+B24)/2 -> -0.5 | H23: 0 | I23: =(1+B24)/2 -> 0.5 | K23: 0 | L23: 10 | M23: -1
A24: ζ | B24: 0 | D24: =-0.5*(1-B22-B23) -> -0.16666667 | E24: =-0.5*B22 -> -0.16666667 | F24: =-0.5*B23 -> -0.16666667 | G24: =0.5*(1-B22-B23) -> 0.16666667 | H24: =0.5*B22 -> 0.16666667 | I24: =0.5*B23 -> 0.16666667 | K24: -0.33333333 | L24: 0 | M24: 5.3333333
D26: N1 | E26: N2 | F26: N3 | G26: N4 | H26: N5 | I26: N6 | K26: NT | M26: NT*N | T26: NT*N*detJ*коэф
D27: =(1-B22-B23)*(1-B24)/2 -> 0.16666667 | E27: =B22*(1-B24)/2 -> 0.16666667 | F27: =B23*(1-B24)/2 -> 0.16666667 | G27: =(1-B22-B23)*(1+B24)/2 -> 0.16666667 | H27: =B22*(1+B24)/2 -> 0.16666667 | I27: =B23*(1+B24)/2 -> 0.16666667 | K27: {=TRANSPOSE(D27:I27)} -> 0.16666667 | M27: {=MMULT(K27:K32,D27:I27)} -> 0.027777778 | N27: 0.027777778 | O27: 0.027777778 | P27: 0.027777778 | Q27: 0.027777778 | R27: 0.027777778 | T27: {=M27*$Q$22} -> 16.203704 | U27: =N27*$Q$22 -> 16.203704 | V27: =O27*$Q$22 -> 16.203704 | W27: =P27*$Q$22 -> 16.203704 | X27: =Q27*$Q$22 -> 16.203704 | Y27: =R27*$Q$22 -> 16.203704
K28: 0.16666667 | M28: 0.027777778 | N28: 0.027777778 | O28: 0.027777778 | P28: 0.027777778 | Q28: 0.027777778 | R28: 0.027777778 | T28: =M28*$Q$22 -> 16.203704 | U28: =N28*$Q$22 -> 16.203704 | V28: =O28*$Q$22 -> 16.203704 | W28: =P28*$Q$22 -> 16.203704 | X28: =Q28*$Q$22 -> 16.203704 | Y28: =R28*$Q$22 -> 16.203704
D29: =SUM(D27:I27) -> 1 | K29: 0.16666667 | M29: 0.027777778 | N29: 0.027777778 | O29: 0.027777778 | P29: 0.027777778 | Q29: 0.027777778 | R29: 0.027777778 | T29: =M29*$Q$22 -> 16.203704 | U29: =N29*$Q$22 -> 16.203704 | V29: =O29*$Q$22 -> 16.203704 | W29: =P29*$Q$22 -> 16.203704 | X29: =Q29*$Q$22 -> 16.203704 | Y29: =R29*$Q$22 -> 16.203704
K30: 0.16666667 | M30: 0.027777778 | N30: 0.027777778 | O30: 0.027777778 | P30: 0.027777778 | Q30: 0.027777778 | R30: 0.027777778 | T30: =M30*$Q$22 -> 16.203704 | U30: =N30*$Q$22 -> 16.203704 | V30: =O30*$Q$22 -> 16.203704 | W30: =P30*$Q$22 -> 16.203704 | X30: =Q30*$Q$22 -> 16.203704 | Y30: =R30*$Q$22 -> 16.203704
K31: 0.16666667 | M31: 0.027777778 | N31: 0.027777778 | O31: 0.027777778 | P31: 0.027777778 | Q31: 0.027777778 | R31: 0.027777778 | T31: =M31*$Q$22 -> 16.203704 | U31: =N31*$Q$22 -> 16.203704 | V31: =O31*$Q$22 -> 16.203704 | W31: =P31*$Q$22 -> 16.203704 | X31: =Q31*$Q$22 -> 16.203704 | Y31: =R31*$Q$22 -> 16.203704
K32: 0.16666667 | M32: 0.027777778 | N32: 0.027777778 | O32: 0.027777778 | P32: 0.027777778 | Q32: 0.027777778 | R32: 0.027777778 | T32: =M32*$Q$22 -> 16.203704 | U32: =N32*$Q$22 -> 16.203704 | V32: =O32*$Q$22 -> 16.203704 | W32: =P32*$Q$22 -> 16.203704 | X32: =Q32*$Q$22 -> 16.203704 | Y32: =R32*$Q$22 -> 16.203704
A34: две точки интегрирвания
A36: ось | B36: координата т. интегр. | D36: производные функции формы dNi/dξ, dNi/dη, dNi/dζ | K36: матрица Якоби [J] | O36: detJ | Q36: detJ* коэф
A37: ξ | B37: =1/3 -> 0.33333333 | D37: =-(1-B39)/2 -> -0.2113 | E37: =(1-B39)/2 -> 0.2113 | F37: 0 | G37: =-(1+B39)/2 -> -0.7887 | H37: =(1+B39)/2 -> 0.7887 | I37: 0 | K37: {=MMULT(D37:I39,A3:C8)} -> 10.4226 | L37: 0 | M37: -1.5774 | O37: =MDETERM(K37:M39) -> 550.614 | Q37: =O37*0.5*1 -> 275.307
A38: η | B38: =1/3 -> 0.33333333 | D38: =-(1-B39)/2 -> -0.2113 | E38: 0 | F38: =(1-B39)/2 -> 0.2113 | G38: =-(1+B39)/2 -> -0.7887 | H38: 0 | I38: =(1+B39)/2 -> 0.7887 | K38: 0 | L38: 10 | M38: -1.5774
A39: ζ | B39: 0.5774 | D39: =-0.5*(1-B37-B38) -> -0.16666667 | E39: =-0.5*B37 -> -0.16666667 | F39: =-0.5*B38 -> -0.16666667 | G39: =0.5*(1-B37-B38) -> 0.16666667 | H39: =0.5*B37 -> 0.16666667 | I39: =0.5*B38 -> 0.16666667 | K39: -0.33333333 | L39: 0 | M39: 5.3333333
D41: N1 | E41: N2 | F41: N3 | G41: N4 | H41: N5 | I41: N6 | K41: NT | M41: NT*N | T41: NT*N*detJ*коэф
D42: =(1-B37-B38)*(1-B39)/2 -> 0.070433333 | E42: =B37*(1-B39)/2 -> 0.070433333 | F42: =B38*(1-B39)/2 -> 0.070433333 | G42: =(1-B37-B38)*(1+B39)/2 -> 0.2629 | H42: =B37*(1+B39)/2 -> 0.2629 | I42: =B38*(1+B39)/2 -> 0.2629 | K42: {=TRANSPOSE(D42:I42)} -> 0.070433333 | M42: {=MMULT(K42:K47,D42:I42)} -> 0.0049608544 | N42: 0.0049608544 | O42: 0.0049608544 | P42: 0.018516923 | Q42: 0.018516923 | R42: 0.018516923 | T42: =M42*$Q$37 -> 1.365758 | U42: =N42*$Q$37 -> 1.365758 | V42: =O42*$Q$37 -> 1.365758 | W42: =P42*$Q$37 -> 5.0978386 | X42: =Q42*$Q$37 -> 5.0978386 | Y42: =R42*$Q$37 -> 5.0978386
K43: 0.070433333 | M43: 0.0049608544 | N43: 0.0049608544 | O43: 0.0049608544 | P43: 0.018516923 | Q43: 0.018516923 | R43: 0.018516923 | T43: =M43*$Q$37 -> 1.365758 | U43: =N43*$Q$37 -> 1.365758 | V43: =O43*$Q$37 -> 1.365758 | W43: =P43*$Q$37 -> 5.0978386 | X43: =Q43*$Q$37 -> 5.0978386 | Y43: =R43*$Q$37 -> 5.0978386
D44: =SUM(D42:I42) -> 1 | K44: 0.070433333 | M44: 0.0049608544 | N44: 0.0049608544 | O44: 0.0049608544 | P44: 0.018516923 | Q44: 0.018516923 | R44: 0.018516923 | T44: =M44*$Q$37 -> 1.365758 | U44: =N44*$Q$37 -> 1.365758 | V44: =O44*$Q$37 -> 1.365758 | W44: =P44*$Q$37 -> 5.0978386 | X44: =Q44*$Q$37 -> 5.0978386 | Y44: =R44*$Q$37 -> 5.0978386
K45: 0.2629 | M45: 0.018516923 | N45: 0.018516923 | O45: 0.018516923 | P45: 0.06911641 | Q45: 0.06911641 | R45: 0.06911641 | T45: =M45*$Q$37 -> 5.0978386 | U45: =N45*$Q$37 -> 5.0978386 | V45: =O45*$Q$37 -> 5.0978386 | W45: =P45*$Q$37 -> 19.028231 | X45: =Q45*$Q$37 -> 19.028231 | Y45: =R45*$Q$37 -> 19.028231
K46: 0.2629 | M46: 0.018516923 | N46: 0.018516923 | O46: 0.018516923 | P46: 0.06911641 | Q46: 0.06911641 | R46: 0.06911641 | T46: =M46*$Q$37 -> 5.0978386 | U46: =N46*$Q$37 -> 5.0978386 | V46: =O46*$Q$37 -> 5.0978386 | W46: =P46*$Q$37 -> 19.028231 | X46: =Q46*$Q$37 -> 19.028231 | Y46: =R46*$Q$37 -> 19.028231
K47: 0.2629 | M47: 0.018516923 | N47: 0.018516923 | O47: 0.018516923 | P47: 0.06911641 | Q47: 0.06911641 | R47: 0.06911641 | T47: =M47*$Q$37 -> 5.0978386 | U47: =N47*$Q$37 -> 5.0978386 | V47: =O47*$Q$37 -> 5.0978386 | W47: =P47*$Q$37 -> 19.028231 | X47: =Q47*$Q$37 -> 19.028231 | Y47: =R47*$Q$37 -> 19.028231
A50: ось | B50: координата т. интегр. | D50: производные функции формы dNi/dξ, dNi/dη, dNi/dζ | K50: матрица Якоби [J] | O50: detJ | Q50: detJ* коэф
A51: ξ | B51: =1/3 -> 0.33333333 | D51: =-(1-B53)/2 -> -0.7887 | E51: =(1-B53)/2 -> 0.7887 | F51: 0 | G51: =-(1+B53)/2 -> -0.2113 | H51: =(1+B53)/2 -> 0.2113 | I51: 0 | K51: {=MMULT(D51:I53,A3:C8)} -> 11.5774 | L51: 0 | M51: -0.4226 | O51: =MDETERM(K51:M53) -> 616.05267 | Q51: =O51*0.5*1 -> 308.02633
A52: η | B52: =1/3 -> 0.33333333 | D52: =-(1-B53)/2 -> -0.7887 | E52: 0 | F52: =(1-B53)/2 -> 0.7887 | G52: =-(1+B53)/2 -> -0.2113 | H52: 0 | I52: =(1+B53)/2 -> 0.2113 | K52: 0 | L52: 10 | M52: -0.4226
A53: ζ | B53: -0.5774 | D53: =-0.5*(1-B51-B52) -> -0.16666667 | E53: =-0.5*B51 -> -0.16666667 | F53: =-0.5*B52 -> -0.16666667 | G53: =0.5*(1-B51-B52) -> 0.16666667 | H53: =0.5*B51 -> 0.16666667 | I53: =0.5*B52 -> 0.16666667 | K53: -0.33333333 | L53: 0 | M53: 5.3333333
D55: N1 | E55: N2 | F55: N3 | G55: N4 | H55: N5 | I55: N6 | K55: NT | M55: NT*N | T55: NT*N*detJ*коэф
D56: =(1-B51-B52)*(1-B53)/2 -> 0.2629 | E56: =B51*(1-B53)/2 -> 0.2629 | F56: =B52*(1-B53)/2 -> 0.2629 | G56: =(1-B51-B52)*(1+B53)/2 -> 0.070433333 | H56: =B51*(1+B53)/2 -> 0.070433333 | I56: =B52*(1+B53)/2 -> 0.070433333 | K56: {=TRANSPOSE(D56:I56)} -> 0.2629 | M56: {=MMULT(K56:K61,D56:I56)} -> 0.06911641 | N56: 0.06911641 | O56: 0.06911641 | P56: 0.018516923 | Q56: 0.018516923 | R56: 0.018516923 | T56: =M56*$Q$51 -> 21.289674 | U56: =N56*$Q$51 -> 21.289674 | V56: =O56*$Q$51 -> 21.289674 | W56: =P56*$Q$51 -> 5.7037 | X56: =Q56*$Q$51 -> 5.7037 | Y56: =R56*$Q$51 -> 5.7037
K57: 0.2629 | M57: 0.06911641 | N57: 0.06911641 | O57: 0.06911641 | P57: 0.018516923 | Q57: 0.018516923 | R57: 0.018516923 | T57: =M57*$Q$51 -> 21.289674 | U57: =N57*$Q$51 -> 21.289674 | V57: =O57*$Q$51 -> 21.289674 | W57: =P57*$Q$51 -> 5.7037 | X57: =Q57*$Q$51 -> 5.7037 | Y57: =R57*$Q$51 -> 5.7037
K58: 0.2629 | M58: 0.06911641 | N58: 0.06911641 | O58: 0.06911641 | P58: 0.018516923 | Q58: 0.018516923 | R58: 0.018516923 | T58: =M58*$Q$51 -> 21.289674 | U58: =N58*$Q$51 -> 21.289674 | V58: =O58*$Q$51 -> 21.289674 | W58: =P58*$Q$51 -> 5.7037 | X58: =Q58*$Q$51 -> 5.7037 | Y58: =R58*$Q$51 -> 5.7037
D59: =SUM(D56:I56) -> 1 | K59: 0.070433333 | M59: 0.018516923 | N59: 0.018516923 | O59: 0.018516923 | P59: 0.0049608544 | Q59: 0.0049608544 | R59: 0.0049608544 | T59: =M59*$Q$51 -> 5.7037 | U59: =N59*$Q$51 -> 5.7037 | V59: =O59*$Q$51 -> 5.7037 | W59: =P59*$Q$51 -> 1.5280738 | X59: =Q59*$Q$51 -> 1.5280738 | Y59: =R59*$Q$51 -> 1.5280738
...

Sheet +NTNdetJ для гексы
B3: x | C3: y | D3: z | F3: коэф | H3: точки интегрирования
A4: 1 | B4: ='+!V гексы через якобиан'!B3 -> 0 | C4: ='+!V гексы через якобиан'!C3 -> 0 | D4: ='+!V гексы через якобиан'!D3 -> 0 | F4: =1/8 -> 0.125 | H4: 0.57735
A5: 2 | B5: ='+!V гексы через якобиан'!B4 -> 12 | C5: ='+!V гексы через якобиан'!C4 -> 0 | D5: ='+!V гексы через якобиан'!D4 -> 0 | H5: =-H4 -> -0.57735
A6: 3 | B6: ='+!V гексы через якобиан'!B5 -> 10 | C6: ='+!V гексы через якобиан'!C5 -> 10 | D6: ='+!V гексы через якобиан'!D5 -> 0
A7: 4 | B7: ='+!V гексы через якобиан'!B6 -> 0 | C7: ='+!V гексы через якобиан'!C6 -> 10 | D7: ='+!V гексы через якобиан'!D6 -> 0
A8: 5 | B8: ='+!V гексы через якобиан'!B7 -> 0 | C8: ='+!V гексы через якобиан'!C7 -> 0 | D8: ='+!V гексы через якобиан'!D7 -> 12
A9: 6 | B9: ='+!V гексы через якобиан'!B8 -> 10 | C9: ='+!V гексы через якобиан'!C8 -> 0 | D9: ='+!V гексы через якобиан'!D8 -> 10
A10: 7 | B10: ='+!V гексы через якобиан'!B9 -> 10 | C10: ='+!V гексы через якобиан'!C9 -> 10 | D10: ='+!V гексы через якобиан'!D9 -> 7
A11: 8 | B11: ='+!V гексы через якобиан'!B10 -> 0 | C11: ='+!V гексы через якобиан'!C10 -> 10 | D11: ='+!V гексы через якобиан'!D10 -> 10
W13: =W15+W30+W45+W60+W75+W90+W105+W120 -> 1020
A14: слагаемые | B14: ось | C14: координата т. интегр. | E14: производные функции формы | N14: матрица Якоби (без коэффициента 1/8) | R14: матрица Якоби | V14: det[J] | W14: det[J]* коэф | X14: коэф2
A15: 1 | B15: ξ | C15: 0.57735 | E15: =-(1-C16)*(1-C17) -> -0.17863302 | F15: =(1-C16)*(1-C17) -> 0.17863302 | G15: =(1+C16)*(1-C17) -> 0.66666698 | H15: =-(1+C16)*(1-C17) -> -0.66666698 | I15: =-(1-C16)*(1+C17) -> -0.66666698 | J15: =(1-C16)*(1+C17) -> 0.66666698 | K15: =(1+C16)*(1+C17) -> 2.488033 | L15: =-(1+C16)*(1+C17) -> -2.488033 | N15: {=MMULT(E15:L17,$B$4:$D$11)} -> 40.357266 | O15: 0 | P15: -8.797433 | R15: =$F$4*N15 -> 5.0446583 | S15: =$F$4*O15 -> 0 | T15: =$F$4*P15 -> -1.0996791 | V15: =MDETERM(R15:T17) -> 102.79284 | W15: =V15*X15 -> 102.79284 | X15: 1
B16: η | C16: 0.57735 | E16: =-(1-C15)*(1-C17) -> -0.17863302 | F16: =-(1+C15)*(1-C17) -> -0.66666698 | G16: =(1+C15)*(1-C17) -> 0.66666698 | H16: =(1-C15)*(1-C17) -> 0.17863302 | I16: =-(1-C15)*(1+C17) -> -0.66666698 | J16: =-(1+C15)*(1+C17) -> -2.488033 | K16: =(1+C15)*(1+C17) -> 2.488033 | L16: =(1-C15)*(1+C17) -> 0.66666698 | N16: -1.333334 | O16: 40 | P16: -8.797433 | R16: =$F$4*N16 -> -0.16666674 | S16: =$F$4*O16 -> 5 | T16: =$F$4*P16 -> -1.0996791
B17: ζ | C17: 0.57735 | E17: =-(1-C15)*(1-C16) -> -0.17863302 | F17: =-(1+C15)*(1-C16) -> -0.66666698 | G17: =-(1+C15)*(1+C16) -> -2.488033 | H17: =-(1-C15)*(1+C16) -> -0.66666698 | I17: =(1-C15)*(1-C16) -> 0.17863302 | J17: =(1+C15)*(1-C16) -> 0.66666698 | K17: =(1+C15)*(1+C16) -> 2.488033 | L17: =(1-C15)*(1+C16) -> 0.66666698 | N17: -1.333334 | O17: 0 | P17: 32.893167 | R17: =$F$4*N17 -> -0.16666674 | S17: =$F$4*O17 -> 0 | T17: =$F$4*P17 -> 4.1116459
E19: N1 | F19: N2 | G19: N3 | H19: N4 | I19: N5 | J19: N6 | K19: N7 | L19: N8 | N19: NT | P19: NT*N | Y19: NT*N*detJ
E20: =(1-C15)*(1-C16)*(1-C17)/8 -> 0.0094374059 | F20: =(1+C15)*(1-C16)*(1-C17)/8 -> 0.03522085 | G20: =(1+C15)*(1+C16)*(1-C17)/8 -> 0.13144589 | H20: =(1-C15)*(1+C16)*(1-C17)/8 -> 0.03522085 | I20: =(1-C15)*(1-C16)*(1+C17)/8 -> 0.03522085 | J20: =(1+C15)*(1-C16)*(1+C17)/8 -> 0.13144589 | K20: =(1+C15)*(1+C16)*(1+C17)/8 -> 0.49056236 | L20: =(1-C15)*(1+C16)*(1+C17)/8 -> 0.13144589 | N20: {=TRANSPOSE(E20:L20)} -> 0.0094374059 | P20: {=MMULT(N20:N27,E20:L20)} -> 8.906463e-05 | Q20: 0.00033239345 | R20: 0.0012405083 | S20: 0.00033239345 | T20: 0.00033239345 | U20: 0.0012405083 | V20: 0.0046296361 | W20: 0.0012405083 | Y20: {=P20*$W$15} -> 0.0091552064 | Z20: =Q20*$W$15 -> 0.034167668 | AA20: =R20*$W$15 -> 0.12751537 | AB20: =S20*$W$15 -> 0.034167668 | AC20: =T20*$W$15 -> 0.034167668 | AD20: =U20*$W$15 -> 0.12751537 | AE20: =V20*$W$15 -> 0.47589345 | AF20: =W20*$W$15 -> 0.12751537
N21: 0.03522085 | P21: 0.00033239345 | Q21: 0.0012405083 | R21: 0.0046296361 | S21: 0.0012405083 | T21: 0.0012405083 | U21: 0.0046296361 | V21: 0.017278023 | W21: 0.0046296361 | Y21: =P21*$W$15 -> 0.034167668 | Z21: =Q21*$W$15 -> 0.12751537 | AA21: =R21*$W$15 -> 0.47589345 | AB21: =S21*$W$15 -> 0.12751537 | AC21: =T21*$W$15 -> 0.12751537 | AD21: =U21*$W$15 -> 0.47589345 | AE21: =V21*$W$15 -> 1.7760571 | AF21: =W21*$W$15 -> 0.47589345
N22: 0.13144589 | P22: 0.0012405083 | Q22: 0.0046296361 | R22: 0.017278023 | S22: 0.0046296361 | T22: 0.0046296361 | U22: 0.017278023 | V22: 0.064482408 | W22: 0.017278023 | Y22: =P22*$W$15 -> 0.12751537 | Z22: =Q22*$W$15 -> 0.47589345 | AA22: =R22*$W$15 -> 1.7760571 | AB22: =S22*$W$15 -> 0.47589345 | AC22: =T22*$W$15 -> 0.47589345 | AD22: =U22*$W$15 -> 1.7760571 | AE22: =V22*$W$15 -> 6.62833 | AF22: =W22*$W$15 -> 1.7760571
N23: 0.03522085 | P23: 0.00033239345 | Q23: 0.0012405083 | R23: 0.0046296361 | S23: 0.0012405083 | T23: 0.0012405083 | U23: 0.0046296361 | V23: 0.017278023 | W23: 0.0046296361 | Y23: =P23*$W$15 -> 0.034167668 | Z23: =Q23*$W$15 -> 0.12751537 | AA23: =R23*$W$15 -> 0.47589345 | AB23: =S23*$W$15 -> 0.12751537 | AC23: =T23*$W$15 -> 0.12751537 | AD23: =U23*$W$15 -> 0.47589345 | AE23: =V23*$W$15 -> 1.7760571 | AF23: =W23*$W$15 -> 0.47589345
N24: 0.03522085 | P24: 0.00033239345 | Q24: 0.0012405083 | R24: 0.0046296361 | S24: 0.0012405083 | T24: 0.0012405083 | U24: 0.0046296361 | V24: 0.017278023 | W24: 0.0046296361 | Y24: =P24*$W$15 -> 0.034167668 | Z24: =Q24*$W$15 -> 0.12751537 | AA24: =R24*$W$15 -> 0.47589345 | AB24: =S24*$W$15 -> 0.12751537 | AC24: =T24*$W$15 -> 0.12751537 | AD24: =U24*$W$15 -> 0.47589345 | AE24: =V24*$W$15 -> 1.7760571 | AF24: =W24*$W$15 -> 0.47589345
N25: 0.13144589 | P25: 0.0012405083 | Q25: 0.0046296361 | R25: 0.017278023 | S25: 0.0046296361 | T25: 0.0046296361 | U25: 0.017278023 | V25: 0.064482408 | W25: 0.017278023 | Y25: =P25*$W$15 -> 0.12751537 | Z25: =Q25*$W$15 -> 0.47589345 | AA25: =R25*$W$15 -> 1.7760571 | AB25: =S25*$W$15 -> 0.47589345 | AC25: =T25*$W$15 -> 0.47589345 | AD25: =U25*$W$15 -> 1.7760571 | AE25: =V25*$W$15 -> 6.62833 | AF25: =W25*$W$15 -> 1.7760571
N26: 0.49056236 | P26: 0.0046296361 | Q26: 0.017278023 | R26: 0.064482408 | S26: 0.017278023 | T26: 0.017278023 | U26: 0.064482408 | V26: 0.24065143 | W26: 0.064482408 | Y26: =P26*$W$15 -> 0.47589345 | Z26: =Q26*$W$15 -> 1.7760571 | AA26: =R26*$W$15 -> 6.62833 | AB26: =S26*$W$15 -> 1.7760571 | AC26: =T26*$W$15 -> 1.7760571 | AD26: =U26*$W$15 -> 6.62833 | AE26: =V26*$W$15 -> 24.737244 | AF26: =W26*$W$15 -> 6.62833
N27: 0.13144589 | P27: 0.0012405083 | Q27: 0.0046296361 | R27: 0.017278023 | S27: 0.0046296361 | T27: 0.0046296361 | U27: 0.017278023 | V27: 0.064482408 | W27: 0.017278023 | Y27: =P27*$W$15 -> 0.12751537 | Z27: =Q27*$W$15 -> 0.47589345 | AA27: =R27*$W$15 -> 1.7760571 | AB27: =S27*$W$15 -> 0.47589345 | AC27: =T27*$W$15 -> 0.47589345 | AD27: =U27*$W$15 -> 1.7760571 | AE27: =V27*$W$15 -> 6.62833 | AF27: =W27*$W$15 -> 1.7760571
A29: слагаемые | B29: ось | C29: координата т. интегр. | E29: производные функции формы | N29: матрица Якоби (без коэффициента 1/8) | R29: матрица Якоби | V29: det[J] | W29: det[J]* коэф | X29: коэф2
A30: 2 | B30: ξ | C30: 0.57735 | E30: =-(1-C31)*(1-C32) -> -0.66666698 | F30: =(1-C31)*(1-C32) -> 0.66666698 | G30: =(1+C31)*(1-C32) -> 2.488033 | H30: =-(1+C31)*(1-C32) -> -2.488033 | I30: =-(1-C31)*(1+C32) -> -0.17863302 | J30: =(1-C31)*(1+C32) -> 0.17863302 | K30: =(1+C31)*(1+C32) -> 0.66666698 | L30: =-(1+C31)*(1+C32) -> -0.66666698 | N30: {=MMULT(E30:L32,$B$4:$D$11)} -> 41.333334 | O30: 0 | P30: -2.357267 | R30: =$F$4*N30 -> 5.1666667 | S30: =$F$4*O30 -> 0 | T30: =$F$4*P30 -> -0.29465837 | V30: =MDETERM(R30:T32) -> 105.97197 | W30: =V30*X30 -> 105.97197 | X30: 1
B31: η | C31: 0.57735 | E31: =-(1-C30)*(1-C32) -> -0.66666698 | F31: =-(1+C30)*(1-C32) -> -2.488033 | G31: =(1+C30)*(1-C32) -> 2.488033 | H31: =(1-C30)*(1-C32) -> 0.66666698 | I31: =-(1-C30)*(1+C32) -> -0.17863302 | J31: =-(1+C30)*(1+C32) -> -0.66666698 | K31: =(1+C30)*(1+C32) -> 0.66666698 | L31: =(1-C30)*(1+C32) -> 0.17863302 | N31: -4.976066 | O31: 40 | P31: -2.357267 | R31: =$F$4*N31 -> -0.62200826 | S31: =$F$4*O31 -> 5 | T31: =$F$4*P31 -> -0.29465837
B32: ζ | C32: -0.57735 | E32: =-(1-C30)*(1-C31) -> -0.17863302 | F32: =-(1+C30)*(1-C31) -> -0.66666698 | G32: =-(1+C30)*(1+C31) -> -2.488033 | H32: =-(1-C30)*(1+C31) -> -0.66666698 | I32: =(1-C30)*(1-C31) -> 0.17863302 | J32: =(1+C30)*(1-C31) -> 0.66666698 | K32: =(1+C30)*(1+C31) -> 2.488033 | L32: =(1-C30)*(1+C31) -> 0.66666698 | N32: -1.333334 | O32: 0 | P32: 32.893167 | R32: =$F$4*N32 -> -0.16666674 | S32: =$F$4*O32 -> 0 | T32: =$F$4*P32 -> 4.1116459
E34: N1 | F34: N2 | G34: N3 | H34: N4 | I34: N5 | J34: N6 | K34: N7 | L34: N8 | N34: NT | P34: NT*N | Y34: NT*N*detJ
E35: =(1-C30)*(1-C31)*(1-C32)/8 -> 0.03522085 | F35: =(1+C30)*(1-C31)*(1-C32)/8 -> 0.13144589 | G35: =(1+C30)*(1+C31)*(1-C32)/8 -> 0.49056236 | H35: =(1-C30)*(1+C31)*(1-C32)/8 -> 0.13144589 | I35: =(1-C30)*(1-C31)*(1+C32)/8 -> 0.0094374059 | J35: =(1+C30)*(1-C31)*(1+C32)/8 -> 0.03522085 | K35: =(1+C30)*(1+C31)*(1+C32)/8 -> 0.13144589 | L35: =(1-C30)*(1+C31)*(1+C32)/8 -> 0.03522085 | N35: {=TRANSPOSE(E35:L35)} -> 0.03522085 | P35: {=MMULT(N35:N42,E35:L35)} -> 0.0012405083 | Q35: 0.0046296361 | R35: 0.017278023 | S35: 0.0046296361 | T35: 0.00033239345 | U35: 0.0012405083 | V35: 0.0046296361 | W35: 0.0012405083 | Y35: =P35*$W$15 -> 0.12751537 | Z35: =Q35*$W$15 -> 0.47589345 | AA35: =R35*$W$15 -> 1.7760571 | AB35: =S35*$W$15 -> 0.47589345 | AC35: =T35*$W$15 -> 0.034167668 | AD35: =U35*$W$15 -> 0.12751537 | AE35: =V35*$W$15 -> 0.47589345 | AF35: =W35*$W$15 -> 0.12751537
N36: 0.13144589 | P36: 0.0046296361 | Q36: 0.017278023 | R36: 0.064482408 | S36: 0.017278023 | T36: 0.0012405083 | U36: 0.0046296361 | V36: 0.017278023 | W36: 0.0046296361 | Y36: =P36*$W$15 -> 0.47589345 | Z36: =Q36*$W$15 -> 1.7760571 | AA36: =R36*$W$15 -> 6.62833 | AB36: =S36*$W$15 -> 1.7760571 | AC36: =T36*$W$15 -> 0.12751537 | AD36: =U36*$W$15 -> 0.47589345 | AE36: =V36*$W$15 -> 1.7760571 | AF36: =W36*$W$15 -> 0.47589345
N37: 0.49056236 | P37: 0.017278023 | Q37: 0.064482408 | R37: 0.24065143 | S37: 0.064482408 | T37: 0.0046296361 | U37: 0.017278023 | V37: 0.064482408 | W37: 0.017278023 | Y37: =P37*$W$15 -> 1.7760571 | Z37: =Q37*$W$15 -> 6.62833 | AA37: =R37*$W$15 -> 24.737244 | AB37: =S37*$W$15 -> 6.62833 | AC37: =T37*$W$15 -> 0.47589345 | AD37: =U37*$W$15 -> 1.7760571 | AE37: =V37*$W$15 -> 6.62833 | AF37: =W37*$W$15 -> 1.7760571
N38: 0.13144589 | P38: 0.0046296361 | Q38: 0.017278023 | R38: 0.064482408 | S38: 0.017278023 | T38: 0.0012405083 | U38: 0.0046296361 | V38: 0.017278023 | W38: 0.0046296361 | Y38: =P38*$W$15 -> 0.47589345 | Z38: =Q38*$W$15 -> 1.7760571 | AA38: =R38*$W$15 -> 6.62833 | AB38: =S38*$W$15 -> 1.7760571 | AC38: =T38*$W$15 -> 0.12751537 | AD38: =U38*$W$15 -> 0.47589345 | AE38: =V38*$W$15 -> 1.7760571 | AF38: =W38*$W$15 -> 0.47589345
N39: 0.0094374059 | P39: 0.00033239345 | Q39: 0.0012405083 | R39: 0.0046296361 | S39: 0.0012405083 | T39: 8.906463e-05 | U39: 0.00033239345 | V39: 0.0012405083 | W39: 0.00033239345 | Y39: =P39*$W$15 -> 0.034167668 | Z39: =Q39*$W$15 -> 0.12751537 | AA39: =R39*$W$15 -> 0.47589345 | AB39: =S39*$W$15 -> 0.12751537 | AC39: =T39*$W$15 -> 0.0091552064 | AD39: =U39*$W$15 -> 0.034167668 | AE39: =V39*$W$15 -> 0.12751537 | AF39: =W39*$W$15 -> 0.034167668
N40: 0.03522085 | P40: 0.0012405083 | Q40: 0.0046296361 | R40: 0.017278023 | S40: 0.0046296361 | T40: 0.00033239345 | U40: 0.0012405083 | V40: 0.0046296361 | W40: 0.0012405083 | Y40: =P40*$W$15 -> 0.12751537 | Z40: =Q40*$W$15 -> 0.47589345 | AA40: =R40*$W$15 -> 1.7760571 | AB40: =S40*$W$15 -> 0.47589345 | AC40: =T40*$W$15 -> 0.034167668 | AD40: =U40*$W$15 -> 0.12751537 | AE40: =V40*$W$15 -> 0.47589345 | AF40: =W40*$W$15 -> 0.12751537
N41: 0.13144589 | P41: 0.0046296361 | Q41: 0.017278023 | R41: 0.064482408 | S41: 0.017278023 | T41: 0.0012405083 | U41: 0.0046296361 | V41: 0.017278023 | W41: 0.0046296361 | Y41: =P41*$W$15 -> 0.47589345 | Z41: =Q41*$W$15 -> 1.7760571 | AA41: =R41*$W$15 -> 6.62833 | AB41: =S41*$W$15 -> 1.7760571 | AC41: =T41*$W$15 -> 0.12751537 | AD41: =U41*$W$15 -> 0.47589345 | AE41: =V41*$W$15 -> 1.7760571 | AF41: =W41*$W$15 -> 0.47589345
N42: 0.03522085 | P42: 0.0012405083 | Q42: 0.0046296361 | R42: 0.017278023 | S42: 0.0046296361 | T42: 0.00033239345 | U42: 0.0012405083 | V42: 0.0046296361 | W42: 0.0012405083 | Y42: =P42*$W$15 -> 0.12751537 | Z42: =Q42*$W$15 -> 0.47589345 | AA42: =R42*$W$15 -> 1.7760571 | AB42: =S42*$W$15 -> 0.47589345 | AC42: =T42*$W$15 -> 0.034167668 | AD42: =U42*$W$15 -> 0.12751537 | AE42: =V42*$W$15 -> 0.47589345 | AF42: =W42*$W$15 -> 0.12751537
A44: слагаемые | B44: ось | C44: координата т. интегр. | E44: производные функции формы | N44: матрица Якоби (без коэффициента 1/8) | R44: матрица Якоби | V44: det[J] | W44: det[J]* коэф | X44: коэф2
A45: 3 | B45: ξ | C45: 0.57735 | E45: =-(1-C46)*(1-C47) -> -0.66666698 | F45: =(1-C46)*(1-C47) -> 0.66666698 | G45: =(1+C46)*(1-C47) -> 0.17863302 | H45: =-(1+C46)*(1-C47) -> -0.17863302 | I45: =-(1-C46)*(1+C47) -> -2.488033 | J45: =(1-C46)*(1+C47) -> 2.488033 | K45: =(1+C46)*(1+C47) -> 0.66666698 | L45: =-(1+C46)*(1+C47) -> -0.66666698 | N45: {=MMULT(E45:L47,$B$4:$D$11)} -> 41.333334 | O45: 0 | P45: -6.976067 | R45: =$F$4*N45 -> 5.1666667 | S45: =$F$4*O45 -> 0 | T45: =$F$4*P45 -> -0.87200837 | V45: =MDETERM(R45:T47) -> 124.30191 | W45: =V45*X45 -> 124.30191 | X45: 1
